Workbook
Name CARGA: 'Matriz datos'!$B$2:$B$9
Name cliente: 'Matriz datos'!$J$2:$J$11
Name INSTRUCCIONES: 'Matriz datos'!$G$2:$G$3
Name TIPO_CARGA: 'Matriz datos'!$C$2:$C$4
Name TIPO_OPERACION: 'Matriz datos'!$D$2:$D$4
Name TIPO_TRAMITE: 'Matriz datos'!$E$2:$E$4

Sheet IMPO TERR
A1: Referencia cliente. | B1: Número de despacho. | C1: ESTADO DE LA CARGA | D1: INSTRUCCIÓN de DESCARGA | E1: Recepción de documentación (FECHA) | F1: CONDICION DOCUMENTAL | G1: Observaciones | H1: Fecha: MODIFICACION SOLICITADA | I1: CORRECCIONES RECEPCIONADAS | J1: FACTURA COMERCIAL | K1: TIPO CARGA | L1: Origen de la carga. | M1: Tipo operacion | N1: Paso aduanero (cuando corresponda). | O1: CONOCIMIENTO EMBARQUE / CRT | P1: MIC | Q1: EMPRESA DE TRANSPORTE | R1: Patente del camión (TRACTO) | S1: Patente del camión (REMOLQUE) | T1: CLIENTE FINAL | U1: Dirección de descarga. DESTINO GD | V1: Nombre chofer | W1: N° IDENTIFICACION | X1: CDA SAG | Y1: IIPA | Z1: CDA SEREMI | AA1: UYD SEREMI | AB1: Fecha de ingreso ALMACENISTA | AC1: FECHA PAPELETA INGRESO | AD1: Fecha de aceptacion DIN | AE1: DIN | AF1: COMPROBANTE PAGO TGR | AG1: Fecha de presentación de documentos.( DESPACHO) | AH1: Fecha de liberación.( SALIDA DE ALMACEN) | AI1: SELLO AGA | AJ1: REMESA | AK1: T/C DOLAR legalizacion | AL1: T/C liberacion carga
A2: O/87250-6 | B2: 179930 | C2: LIBERADO | D2: EMITIDA | E2: 46076 | F2: ok | G2: Solo envio de doctos draft | H2: 46078 | I2: 05/03/2026 09:35 hrs | K2: ENFRIADA | L2: Brasil | M2: TERRESTRE | N2: Los Andes | O2: BR547044923 | P2: 33737 | Q2: MARVEL | R2: SWY2C62 | S2: RYP8I48 | T2: ALMAFRIGO | U2: =VLOOKUP('IMPO TERR'!T2,'Matriz datos'!$J$2:$K$10,2,0) -> AV. GALVARINO 8601 BGA. 11, QUILICURA | V2: FABRICIO ESTEVAO DA CRUZ | W2: CPF: 445.947.978-81 | X2: 0520260012446CDA | Y2: 0520260018764IIPA | Z2: 2605113227 | AA2: 2605114532 | AB2: 46083.86 | AC2: 46084 | AD2: 46087 | AE2: 4090179930 | AF2: 46087.726 | AG2: 46090.479 | AH2: 46090.56 | AJ2: 25010000 | AK2: 0 | AL2: 0
A3: CN 6526-1 | B3: 179947 | C3: LIBERADO | D3: PENDIENTE | E3: 46076 | G3: En espera de resolucion de bodega (minerva) | K3: CONGELADA | L3: Paraguay | M3: TERRESTRE | N3: Los Andes | O3: PY23TMA1134 | P3: 32028 | Q3: TRANSMA | R3: AALJ416 | S3: AALJ421 | T3: CIAL | U3: =VLOOKUP('IMPO TERR'!T3,'Matriz datos'!$J$2:$K$10,2,0) -> CAMINO SANTA MARTA 2101, MAIPU | V3: JUAN PABLO MORINIGO | W3: CI: 3564133 | X3: 0520260011071CDA | Y3: 0520260017940IIPA | Z3: 2605101385 | AA3: 2605109992 | AB3: 46080.908 | AC3: 46081 | AD3: 46085 | AE3: 4090179947 | AF3: 46085.553 | AG3: 46086.655 | AH3: 46093 | AJ3: 6500000 | AK3: 857.58
A4: SO/6370-22 | B4: 179972 | C4: LIBERADO | D4: PENDIENTE | E4: 46077 | F4: DOCS ORIGINALES PENDIENTES | G4: DOCS ORIGINALES PENDIENTES | K4: ENFRIADA | L4: Brasil | M4: TERRESTRE | N4: Los Andes | O4: BR547044933 | P4: 32413 | Q4: MARVEL | R4: RXM4D24 | S4: RLL3F14 | T4: WALMART | U4: =VLOOKUP('IMPO TERR'!T4,'Matriz datos'!$J$2:$K$10,2,0) -> AV. PDTE. EDUARDO FREI 8301, QUILICURA | V4: MARCOS ANTONIO DO CARMO | W4: CPF: 068.976.759-54 | X4: 0520260011763CDA | Y4: 0520260017950IIPA | Z4: 2605106362 | AA4: 2605107634 | AB4: 46082.479 | AC4: 46083 | AD4: 46085 | AE4: 4090179972 | AF4: 46085.653 | AG4: 46085.753 | AH4: 46085.833 | AJ4: 25950000 | AK4: 857.58
A5: SO/6370-23 | B5: 180001 | C5: LIBERADO | D5: PENDIENTE | E5: 46077 | K5: ENFRIADA | L5: Brasil | M5: TERRESTRE | N5: Los Andes | O5: BR547044931 | Q5: MARVEL | R5: RXY9C34 | S5: RXW9H24 | T5: WALMART | U5: =VLOOKUP('IMPO TERR'!T5,'Matriz datos'!$J$2:$K$10,2,0) -> AV. PDTE. EDUARDO FREI 8301, QUILICURA | V5: IVAN DOS SANTOS | W5: CPF: 096.316.418-05 | X5: 0520260010619CDA | Y5: 0520260018425IIPA | Z5: 260595504 | AA5: 260597318 | AB5: 46086.792 | AC5: 46087 | AD5: 46079 | AE5: 4090180001 | AF5: 46087 | AG5: 46087.775 | AH5: 46087.826 | AJ5: 26010000 | AK5: 857.95
A6: SO/6370-26 | B6: 180023 | C6: LIBERADO | D6: PENDIENTE | E6: 46078 | K6: ENFRIADA | L6: Brasil | M6: TERRESTRE | N6: Los Andes | O6: BR547044941 | P6: 34269 | Q6: MARVEL | R6: QJG8563 | S6: SXW7I81 | T6: WALMART | U6: =VLOOKUP('IMPO TERR'!T6,'Matriz datos'!$J$2:$K$10,2,0) -> AV. PDTE. EDUARDO FREI 8301, QUILICURA | V6: WESLEM DO NASCIMENTO | W6: CPF: 042.438.270-95 | X6: 0520260010919CDA | Y6: 0520260017584IIPA | Z6: 260598254 | AA6: 260599583 | AB6: 46084.791 | AC6: 46085 | AD6: 46080 | AE6: 4090180023 | AF6: 46085 | AG6: 46084.791 | AH6: 46085.734 | AJ6: 25520000 | AK6: 857.95
A7: CN 25221 | B7: 180040 | C7: LIBERADO | D7: PENDIENTE | E7: 46078 | K7: ENFRIADA | L7: Paraguay | M7: TERRESTRE | N7: Los Andes | O7: 2026PYSANJOSE044 | Q7: SAN JOSE | R7: TISJ001 | S7: TISJ004 | T7: ICESTAR | U7: =VLOOKUP('IMPO TERR'!T7,'Matriz datos'!$J$2:$K$10,2,0) -> AV. AMERICO VESPUCIO 0350, QUILICURA | V7: HUGO ARIEL MORINIGO | W7: CI: 5.497.180 | X7: 0520260011333CDA | Y7: 0520260017640IIPA | Z7: 2605101685 | AA7: 2605107573 | AB7: 46082.751 | AC7: 46083 | AD7: 46084 | AE7: 4090180040 | AF7: 46084 | AG7: 46085.669 | AH7: 46087.305 | AJ7: 28670000 | AK7: 857.58
A8: SO/6360-28 | B8: 180056 | C8: LIBERADO | D8: PENDIENTE | E8: 46079 | K8: ENFRIADA | L8: Brasil | M8: TERRESTRE | N8: Los Andes | O8: BR547044939 | Q8: MARVEL | R8: RXQ0G36 | S8: RYK0I89 | T8: WALMART | U8: =VLOOKUP('IMPO TERR'!T8,'Matriz datos'!$J$2:$K$10,2,0) -> AV. PDTE. EDUARDO FREI 8301, QUILICURA | V8: EEDISON JORGE NUNES | W8: CPF: 035.606.250-33 | X8: 0520260011336CDA | Y8: 0520260018429IIPA | Z8: 2605101914 | AA8: 2605102768 | AB8: 46086.866 | AC8: 46087 | AD8: 46083 | AE8: 4090180056 | AF8: 46087 | AG8: 46087.779 | AH8: 46087.824 | AJ8: 25880000 | AK8: 857.58
A9: SO/6360-25 | B9: 180057 | C9: LIBERADO | D9: PENDIENTE | E9: 46079 | F9: C.O. ERROR | G9: C.O. ERROR | K9: ENFRIADA | L9: Brasil | M9: TERRESTRE | N9: Los Andes | O9: BR547044872 | P9: 32539 | Q9: MARVEL | R9: TDX0H19 | S9: SXM2B63 | T9: WALMART | U9: =VLOOKUP('IMPO TERR'!T9,'Matriz datos'!$J$2:$K$10,2,0) -> AV. PDTE. EDUARDO FREI 8301, QUILICURA | V9: ANDRE LUIZ DE AQUINO SOARES | W9: CPF: 932.708.872-72 | X9: 0520260011220CDA | Y9: 0520260017649IIPA | Z9: 2605100691 | AA9: 2605101997 | AB9: 46082.639 | AC9: 46083 | AD9: 46084 | AE9: 4090180057 | AF9: 46084 | AG9: 46085.596 | AH9: 46085.68 | AJ9: 25770000 | AK9: 857.58
A10: SO/6356-4 | B10: 180059 | C10: LIBERADO | D10: PENDIENTE | E10: 46079 | K10: CONGELADA | L10: Brasil | M10: TERRESTRE | N10: Los Andes | O10: BR453909363 | Q10: BRILHANTE | R10: RHG9B61 | S10: RLA8I71 | T10: WALMART | U10: =VLOOKUP('IMPO TERR'!T10,'Matriz datos'!$J$2:$K$10,2,0) -> AV. PDTE. EDUARDO FREI 8301, QUILICURA | V10: LUCAS PAULO MAIA QUEIROZ DA SILVA | W10: CPF: 903.000.332-4 | X10: 0520260011285CDA | Y10: 0520260018513IIPA | Z10: 2605101437 | AA10: 2605101999 | AB10: 46087.03 | AC10: 46087 | AD10: 46083 | AE10: 4090180059 | AF10: 46087 | AG10: 46088.481 | AH10: 46088.604 | AJ10: 25720000 | AK10: 857.58
A11: O/87304-3 | B11: 180066 | C11: LIBERADO | D11: EMITIDA | E11: 46079 | K11: ENFRIADA | L11: Brasil | M11: TERRESTRE | N11: Los Andes | O11: BR261615121 | Q11: BELMAT | R11: GHG7D55 | S11: RLB4D02 | T11: ICESTAR | U11: =VLOOKUP('IMPO TERR'!T11,'Matriz datos'!$J$2:$K$10,2,0) -> AV. AMERICO VESPUCIO 0350, QUILICURA | V11: MARCELO DINIZ | W11: 195216179 | X11: 0520260011841CDA | Y11: 0520260019347IIPA | Z11: 2605106858 | AA11: 2605107743 | AB11: 46089.87 | AC11: 46090 | AD11: 46085 | AE11: 4090180066 | AF11: 46090 | AG11: 46091 | AH11: 46092 | AI11: 141542 | AJ11: 25180000 | AK11: 857.58
A12: SO/6356-5 | B12: 180067 | C12: LIBERADO | D12: EMITIDA | E12: 46079 | F12: C.O. ERROR | G12: C.O. ERROR | K12: CONGELADA | L12: Brasil | M12: TERRESTRE | N12: Los Andes | O12: BR168811718 | R12: RLB6G92 | S12: MFV6036 | T12: WALMART | U12: =VLOOKUP('IMPO TERR'!T12,'Matriz datos'!$J$2:$K$10,2,0) -> AV. PDTE. EDUARDO FREI 8301, QUILICURA | V12: HENRIQUE CORREIA | W12: CPF: 225.355.138-46 | X12: 0520260011208CDA | Y12: 0520260018794IIPA | Z12: 2605100503 | AA12: 2605102001 | AB12: 46089.755 | AC12: 09-03-2026 | AD12: 46083 | AE12: 4090180067 | AF12: 46090 | AG12: 46090.659 | AH12: 46090 | AI12: 141496 | AJ12: 24360000 | AK12: 857.58
A13: CN 6357-10 | B13: 180070 | C13: LIBERADO | D13: PENDIENTE | E13: 46079 | K13: ENFRIADA | L13: Paraguay | M13: TERRESTRE | N13: Los Andes | O13: 2026PYSANJOSE049 | Q13: SAN JOSE | R13: LJWL11 | S13: KDHS40 | T13: WALMART | U13: =VLOOKUP('IMPO TERR'!T13,'Matriz datos'!$J$2:$K$10,2,0) -> AV. PDTE. EDUARDO FREI 8301, QUILICURA | V13: REINALDO COLMAN | W13: 28.142.153-0 | X13: 0520260011782CDA | Y13: 0520260017968IIPA | Z13: 2605106749 | AA13: 2605107710 | AB13: 46083.877 | AC13: 46084 | AD13: 46085 | AE13: 4090180070 | AF13: 46085 | AG13: 46085.771 | AH13: 46087.752 | AJ13: 27110000 | AK13: 857.58
A14: CN 6358-10 | B14: 180072 | C14: LIBERADO | D14: PENDIENTE | E14: 46079 | K14: ENFRIADA | L14: Paraguay | M14: TERRESTRE | N14: Los Andes | O14: 26PYFOODS314 | Q14: FRIGOMERC | R14: AAAE804 | S14: AAAE476 | T14: WALMART | U14: =VLOOKUP('IMPO TERR'!T14,'Matriz datos'!$J$2:$K$10,2,0) -> AV. PDTE. EDUARDO FREI 8301, QUILICURA | V14: PEDRO EMILIO CACERES | W14: CI 4.183.555 | X14: 0520260011535CDA | Y14: 0520260018254IIPA | Z14: 2605104506 | AA14: 2605105058 | AB14: 46084.793 | AC14: 46085 | AD14: 46085 | AE14: 4090180072 | AF14: 46085 | AG14: 46085.748 | AH14: 46091 | AJ14: 26210000 | AK14: 857.58
A15: CN 6359-8 | B15: 180073 | C15: LIBERADO | D15: PENDIENTE | E15: 46079 | K15: ENFRIADA | L15: Paraguay | M15: TERRESTRE | N15: Los Andes | O15: PYLG066/2026 | P15: 2026 | Q15: LUCERY | R15: AAGN977 | S15: AAAE634 | T15: WALMART | U15: =VLOOKUP('IMPO TERR'!T15,'Matriz datos'!$J$2:$K$10,2,0) -> AV. PDTE. EDUARDO FREI 8301, QUILICURA | V15: DERLIS HERMOSA FLORENTIN | W15: CI 2.889..378 | X15: 0520260011407CDA | Y15: 0520260017775IIPA | Z15: 2605103079 | AA15: 2605105078 | AB15: 46084.768 | AC15: 46085 | AD15: 46083 | AE15: 4090180073 | AF15: 46085 | AG15: 46085.597 | AH15: 46087.81 | AJ15: 25670000 | AK15: 857.58
A16: SO/6354-43 | B16: 180074 | C16: LIBERADO | D16: PENDIENTE | E16: 46079 | F16: C.O. VALIDAR | G16: C.O. VALIDAR | K16: ENFRIADA | L16: Brasil | M16: TERRESTRE | N16: Los Andes | O16: BR547044989 | Q16: MARVEL | R16: JBG8A84 | S16: RYM5E22 | T16: WALMART | U16: =VLOOKUP('IMPO TERR'!T16,'Matriz datos'!$J$2:$K$10,2,0) -> AV. PDTE. EDUARDO FREI 8301, QUILICURA | V16: LUCAS MARINGOLO | X16: 0520260011476CDA | Y16: 0520260018502IIPA | Z16: 2605103668 | AA16: 2605105134 | AB16: 46087.571 | AC16: 46088 | AD16: 46084 | AE16: 4090180074 | AF16: 46087 | AG16: 46088.563 | AH16: 46088.638 | AJ16: 24850000 | AK16: 857.58
A17: SO/6354-37 | B17: 180075 | C17: LIBERADO | D17: EMITIDA | E17: 46079 | K17: ENFRIADA | L17: Brasil | M17: TERRESTRE | N17: Los Andes | O17: BR547044911 | R17: RYB8I87 | S17: RYB8I87 | T17: WALMART | U17: =VLOOKUP('IMPO TERR'!T17,'Matriz datos'!$J$2:$K$10,2,0) -> AV. PDTE. EDUARDO FREI 8301, QUILICURA | V17: ALESSANDRO VIEIRA | W17: 39.742.349-77 | X17: 0520260011359CDA | Y17: 0520260018718IIPA | Z17: 2605102035 | AA17: 2605102626 | AB17: 46087.645 | AC17: 46087 | AD17: 46083 | AE17: 4090180075 | AF17: 46087 | AG17: 46090.481 | AH17: 46090.546 | AJ17: 23250000 | AK17: 857.58
A18: CN 25320-6 | B18: 180109 | C18: LIBERADO | D18: PENDIENTE | E18: 46080 | K18: ENFRIADA | L18: Paraguay | M18: TERRESTRE | N18: Los Andes | O18: PYLG070/2026 | P18: 2026 | Q18: LUCERY | R18: AAHI130 | S18: AAKB750 | T18: RAMIREZ | U18: =VLOOKUP('IMPO TERR'!T18,'Matriz datos'!$J$2:$K$10,2,0) -> AV. EL PARRON 345, LA CISTERNA | V18: LORENZO MARECOS | X18: 0520260011416CDA | Y18: 0520260018430IIPA | Z18: 2605103273 | AA18: 2605104792 | AB18: 46087.402 | AC18: 46087 | AD18: 46084 | AE18: 4090180109 | AF18: 46087 | AG18: 46087.778 | AH18: 46091 | AJ18: 28760000 | AK18: 857.58
A19: SO/6354-41 | B19: 180110 | C19: LIBERADO | D19: PENDIENTE | E19: 46080 | K19: ENFRIADA | L19: Brasil | M19: TERRESTRE | N19: Los Andes | O19: BR547044956 | Q19: MARVEL | R19: RYX9E71 | S19: RYP2J71 | T19: WALMART | U19: =VLOOKUP('IMPO TERR'!T19,'Matriz datos'!$J$2:$K$10,2,0) -> AV. PDTE. EDUARDO FREI 8301, QUILICURA | V19: ARLINDO DA SILVA | W19: CPF 013.075.065-42 | X19: 0520260011864CDA | Y19: 0520260018359IIPA | Z19: 2605107269 | AA19: 2605110378 | AB19: 46086.751 | AC19: 46087 | AD19: 46085 | AE19: 4090180110 | AF19: 46087 | AG19: 46087.745 | AH19: 46087.808 | AJ19: 24290000 | AK19: 857.58
A20: O/87315-2 | B20: 180112 | C20: LIBERADO | D20: PENDIENTE | E20: 46080 | K20: ENFRIADA | L20: Brasil | M20: TERRESTRE | N20: Los Andes | O20: BR547044967 | Q20: MARVEL | R20: RXT9I23 | S20: RXO5E92 | T20: ICESTAR | U20: =VLOOKUP('IMPO TERR'!T20,'Matriz datos'!$J$2:$K$10,2,0) -> AV. AMERICO VESPUCIO 0350, QUILICURA | V20: MATHEUS HENRIQUE | W20: CPF 466.739.518-42 | X20: 0520260011897CDA | Y20: 0520260018420IIPA | Z20: 2605107217 | AA20: 2605110317 | AB20: 46087.459 | AC20: 46087 | AD20: 46085 | AE20: 4090180112 | AF20: 46087 | AG20: 46087.788 | AH20: 46088.512 | AJ20: 25920000 | AK20: 857.58
A21: O/87568 | B21: 180114 | C21: LIBERADO | D21: PENDIENTE | E21: 46080 | K21: CONGELADA | L21: Brasil | M21: TERRESTRE | N21: Los Andes | O21: BR698100492 | Q21: VIZZOTTO | R21: RYC0I37 | S21: RLI0I42 | T21: RAMIREZ | U21: =VLOOKUP('IMPO TERR'!T21,'Matriz datos'!$J$2:$K$10,2,0) -> AV. EL PARRON 345, LA CISTERNA | V21: TIRZA MARINUZE DE LARA | W21: CPF 067.225.439-51 | X21: 0520260011917CDA | Y21: 0520260018423IIPA | Z21: 2605107322 | AA21: 2605110277 | AB21: 46087.439 | AC21: 46087 | AD21: 46085 | AE21: 4090180114 | AF21: 46087 | AG21: 46087.777 | AH21: 46088.412 | AJ21: 25840000 | AK21: 857.58
A22: CN 6360-30 | B22: 180115 | C22: LIBERADO | D22: EMITIDA | E22: 46080 | K22: ENFRIADA | L22: Paraguay | M22: TERRESTRE | N22: Los Andes | O22: PYLG072/2026 | P22: 2026 | Q22: LUCERY | R22: AAIE199 | S22: AAMA137 | T22: WALMART | U22: =VLOOKUP('IMPO TERR'!T22,'Matriz datos'!$J$2:$K$10,2,0) -> AV. PDTE. EDUARDO FREI 8301, QUILICURA | V22: FERNANDO ACOSTA AGUILAR | W22: CI 3.532.558 | X22: 0520260011516CDA | Y22: 0520260018850IIPA | Z22: 2605103977 | AA22: 2605104765 | AB22: 46088.769 | AC22: 08-03-2026 | AD22: 46084 | AE22: 4090180115 | AF22: 46090 | AG22: 46090.528 | AH22: 46092 | AI22: 141491 | AJ22: 25470000 | AK22: 857.58
A23: SO/6397-2P | B23: 180133 | C23: LIBERADO | D23: EMITIDA | E23: 46083 | G23: GUIA MOD.DESTINO (RUTA 5 SUR N 2786 KM252-PLANTA 3, TALCA) | K23: CONGELADA | L23: Brasil | M23: TERRESTRE | N23: Los Andes | O23: BR707400447 | Q23: MF | R23: SQA4B99 | S23: SPZ5D39 | T23: ICESTAR | U23: Ruta 5 Sur N 2786 KM 252-Planta 3, Talca | V23: JACSON DOUGLAS LOCH | W23: CPF 044.818.939-90 | X23: 0520260011946CDA | Y23: 0520260018771IIPA | Z23: 2605108712 | AA23: 2605110144 | AB23: 46089.864 | AC23: 46090 | AD23: 46085 | AE23: 4090180133 | AF23: 46090 | AG23: 46090 | AH23: 46090 | AI23: 141489 | AJ23: 16870000 | AK23: 857.58
A24: SO/6456-3 | B24: 180136 | C24: LIBERADO | D24: PENDIENTE | E24: 46083 | K24: CONGELADA | L24: Brasil | M24: TERRESTRE | N24: Los Andes | O24: BR512203456 | Q24: VENEZA | R24: RGM7C35 | S24: QJB2B11 | T24: ICESTAR | U24: =VLOOKUP('IMPO TERR'!T24,'Matriz datos'!$J$2:$K$10,2,0) -> AV. AMERICO VESPUCIO 0350, QUILICURA | V24: RAFAEL GERMANO | W24: CPF 066.643.969-98 | X24: 0520260012067CDA | Y24: 0520260018434IIPA | Z24: 2605109923 | AA24: 2605112548 | AB24: 46086.938 | AC24: 46087 | AD24: 46086 | AE24: 4090180136 | AF24: 46087 | AG24: 46087.777 | AH24: 46088.446 | AJ24: 25980000 | AK24: 857.58
A25: SO/6354-39 | B25: 180137 | C25: LIBERADO | D25: PENDIENTE | E25: 46083 | K25: ENFRIADA | L25: Brasil | M25: TERRESTRE | N25: Los Andes | O25: BR547044938 | P25: 32433 | Q25: MARVEL | R25: SXA9J22 | S25: SXA1F12 | T25: WALMART | U25: =VLOOKUP('IMPO TERR'!T25,'Matriz datos'!$J$2:$K$10,2,0) -> AV. PDTE. EDUARDO FREI 8301, QUILICURA | V25: MAURO MARTINS | W25: CPF 255.154.228-64 | X25: 0520260011881CDA | Y25: 0520260018267IIPA | Z25: 2605106196 | AA25: 2605107984 | AB25: 46082.575 | AC25: 02-03-2026 | AD25: 46085 | AE25: 4090180137 | AF25: 46085 | AG25: 46085.756 | AH25: 46085.835 | AJ25: 24410000 | AK25: 857.58
A26: SO/6370-27 | B26: 180139 | C26: LIBERADO | D26: EMITIDA | E26: 46083 | K26: ENFRIADA | L26: Brasil | M26: TERRESTRE | N26: Los Andes | O26: BR547044995 | Q26: MARVEL | R26: RLI5A86 | S26: RYF1C29 | T26: WALMART | U26: =VLOOKUP('IMPO TERR'!T26,'Matriz datos'!$J$2:$K$10,2,0) -> AV. PDTE. EDUARDO FREI 8301, QUILICURA | V26: STEVAO GARCIA | W26: CPF 730.604.960-72 | X26: 0520260012044CDA | Y26: 0520260018943IIPA | Z26: 2605109152 | AA26: 2605110090 | AB26: 46089.475 | AC26: 46090 | AD26: 46086 | AE26: 4090180139 | AF26: 46090 | AG26: 46090 | AH26: 46091 | AI26: 141504 | AJ26: 25980000 | AK26: 857.58
A27: SO/6354-42 | B27: 180145 | C27: LIBERADO | D27: PENDIENTE | E27: 46083 | K27: ENFRIADA | L27: Brasil | M27: TERRESTRE | N27: Los Andes | O27: BR547044969 | Q27: MARVEL | R27: QTL0655 | S27: RYL9J02 | T27: WALMART | U27: =VLOOKUP('IMPO TERR'!T27,'Matriz datos'!$J$2:$K$10,2,0) -> AV. PDTE. EDUARDO FREI 8301, QUILICURA | V27: ROMEU DOS SANTOS | W27: CPF 536.104.825-91 | X27: 0520260012066CDA | Y27: 0520260018462IIPA | Z27: 2605109255 | AA27: 2605110037 | AB27: 46087.548 | AC27: 46088 | AD27: 46086 | AE27: 4090180145 | AF27: 46088 | AG27: 46088.562 | AH27: 46088.651 | AJ27: 24010000 | AK27: 857.58
A28: SO/6331-15 | B28: 180146 | C28: LIBERADO | D28: PENDIENTE | E28: 46083 | K28: ENFRIADA | L28: Argentina | M28: TERRESTRE | N28: Los Andes | O28: 052024TC2026 | Q28: TRES CRUCES | R28: AG826IT | S28: AG337WM | T28: WALMART | U28: =VLOOKUP('IMPO TERR'!T28,'Matriz datos'!$J$2:$K$10,2,0) -> AV. PDTE. EDUARDO FREI 8301, QUILICURA | V28: ESTRELA MAURICIO ALBERTO | W28: DNI 29.217.376 | X28: 0520260012059CDA | Y28: 0520260018004IIPA | Z28: 2605109265 | AA28: 2605110562 | AB28: 46084.56 | AC28: 46085 | AD28: 46086 | AE28: 4090180146 | AF28: 46086 | AG28: 46086.739 | AH28: 46086.837 | AK28: 857.58
A29: SO/6330-11 | B29: 180147 | C29: LIBERADO | D29: PENDIENTE | E29: 46083 | K29: ENFRIADA | L29: Argentina | M29: TERRESTRE | N29: Los Andes | O29: 052AR219400890 | Q29: RIO COLORADO | R29: RBTW67 | S29: JB6491 | T29: WALMART | U29: =VLOOKUP('IMPO TERR'!T29,'Matriz datos'!$J$2:$K$10,2,0) -> AV. PDTE. EDUARDO FREI 8301, QUILICURA | V29: MARIO TASTACA | W29: CI 27.736874-9 | X29: 0520260011708CDA | Y29: 0520260017620IIPA | Z29: 2605105649 | AA29: 2605107389 | AB29: 46084.081 | AC29: 46084 | AD29: 46085 | AE29: 4090180147 | AF29: 46085 | AG29: 46085.672 | AH29: 46088.468 | AK29: 857.58
A30: SO/6354-38 | B30: 180152 | C30: LIBERADO | D30: EMITIDA | E30: 46083 | K30: ENFRIADA | L30: Brasil | M30: TERRESTRE | N30: Los Andes | O30: BR547044953 | Q30: MARVEL | R30: RDS0192 | S30: TPY4177 | T30: WALMART | U30: =VLOOKUP('IMPO TERR'!T30,'Matriz datos'!$J$2:$K$10,2,0) -> AV. PDTE. EDUARDO FREI 8301, QUILICURA | V30: JOAO CARLOS ALVES | W30: CPF: 714.674.756-53 | X30: 0520260012068CDA | Y30: 0520260019904IIPA | Z30: 2605109941 | AA30: 2605112533 | AB30: 46091 | AC30: 46092 | AD30: 46086 | AE30: 4090180152 | AF30: 46091 | AG30: 46092 | AH30: 46092 | AI30: 141548 | AK30: 857.58
A31: O/87772-1 | B31: 180153 | C31: LIBERADO | D31: PENDIENTE | E31: 46083 | K31: CONGELADA | L31: Brasil | M31: TERRESTRE | N31: Los Andes | O31: BR547044927 | Q31: MARVEL | R31: RLM6H97 | S31: QIT8604 | T31: ICESTAR | U31: =VLOOKUP('IMPO TERR'!T31,'Matriz datos'!$J$2:$K$10,2,0) -> AV. AMERICO VESPUCIO 0350, QUILICURA | V31: JOSE MAURO VIDEIRA | W31: CPF 283.898.578-71 | X31: 0520260011858CDA | Y31: 0520260018501IIPA/0520260018500IIPA | Z31: 2605105906 | AA31: 2605107383 | AB31: 46087.731 | AC31: 46088 | AD31: 46085 | AE31: 4090180153 | AF31: 46088 | AG31: 46088.574 | AH31: 46088.648 | AK31: 857.58
A32: O/87772-2 | B32: 180154 | C32: LIBERADO | D32: EMITIDA | E32: 46083 | K32: CONGELADA | L32: Brasil | M32: TERRESTRE | N32: Los Andes | O32: BR547045030 | Q32: MARVEL | R32: TDQ9I41 | S32: SXV1F31 | T32: ICESTAR | U32: =VLOOKUP('IMPO TERR'!T32,'Matriz datos'!$J$2:$K$10,2,0) -> AV. AMERICO VESPUCIO 0350, QUILICURA | V32: JOSE PAGOTTI | W32: CPF 108.083.478-88 | X32: 0520260012143CDA | Y32: 0520260018941IIPA/0520260018942IIPA | Z32: 2605109424 | AA32: 2605110377 | AB32: 46089.969 | AC32: 46090 | AD32: 46086 | AE32: 4090180154 | AF32: 46090 | AG32: 46090 | AH32: 46090 | AI32: 141505 | AK32: 857.58
A33: SO/6360-31 | B33: 180178 | C33: LIBERADO | D33: EMITIDA | E33: 46084 | K33: ENFRIADA | L33: Brasil | M33: TERRESTRE | N33: Los Andes | O33: BR547045033 | Q33: MARVEL | R33: RXZ4F56 | S33: RYC8F45 | T33: WALMART | U33: =VLOOKUP('IMPO TERR'!T33,'Matriz datos'!$J$2:$K$10,2,0) -> AV. PDTE. EDUARDO FREI 8301, QUILICURA | V33: ALEX SANDRO GARCEZ AMARO | W33: CPF: 012.846.590-54 | X33: 0520260012308CDA | Y33: 0520260019893IIPA | Z33: 2605111544 | AA33: 2605112433 | AB33: 46091 | AC33: 46092 | AD33: 46087 | AE33: 4090180178 | AF33: 46091 | AG33: 46092 | AH33: 46092 | AI33: 141553 | AK33: 857.58
A34: SO/6354-45 | B34: 180180 | C34: LIBERADO | D34: EMITIDA | E34: 46084 | K34: ENFRIADA | L34: Brasil | M34: TERRESTRE | N34: Los Andes | O34: BR547045016 | Q34: MARVEL | R34: RXY9E54 | S34: RXK1C65 | T34: WALMART | U34: =VLOOKUP('IMPO TERR'!T34,'Matriz datos'!$J$2:$K$10,2,0) -> AV. PDTE. EDUARDO FREI 8301, QUILICURA | V34: MARCIO DA SILVA | W34: CPF 256.358.608-93 | X34: 0520260011913CDA | Y34: 0520260019321IIPA | Z34: 2605108064 | AA34: 2605109863 | AB34: 46090.494 | AC34: 46091 | AD34: 46086 | AE34: 4090180180 | AF34: 46090 | AG34: 46091 | AH34: 46091 | AI34: 141522 | AK34: 857.58
A35: SO/6370-29 | B35: 180181 | C35: LIBERADO | D35: EMITIDA | E35: 46084 | K35: ENFRIADA | L35: Brasil | M35: TERRESTRE | N35: Los Andes | O35: BR547045026 | Q35: MARVEL | R35: SXI7A02 | S35: RYW5J12 | T35: WALMART | U35: =VLOOKUP('IMPO TERR'!T35,'Matriz datos'!$J$2:$K$10,2,0) -> AV. PDTE. EDUARDO FREI 8301, QUILICURA | V35: ELIO PEREIRA DE OLIVEIRA | W35: CPF 829.160-129-15 | X35: 0520260012190CDA | Y35: 0520260019259IIPA | Z35: 2605109685 | AA35: 2605110139 | AB35: 46090 | AC35: 46091 | AD35: 46086 | AE35: 4090180181 | AF35: 46091 | AG35: 46091 | AH35: 46091 | AI35: 141526 | AK35: 857.58
A36: SO/6354-46 | B36: 180183 | C36: LIBERADO | D36: EMITIDA | E36: 46084 | K36: ENFRIADA | L36: Brasil | M36: TERRESTRE | N36: Los Andes | O36: BR547045038 | P36: 40365 | Q36: MARVEL | R36: RXW2G34 | S36: SXA7D71 | T36: WALMART | U36: =VLOOKUP('IMPO TERR'!T36,'Matriz datos'!$J$2:$K$10,2,0) -> AV. PDTE. EDUARDO FREI 8301, QUILICURA | V36: GABRIEL CAMARGO FORTES | W36: CPF:446.710.208-66 | X36: 0520260012109CDA | Y36: 0520260020948IIPA | Z36: 2605109639 | AA36: 2605110120 | AB36: 46094 | AC36: 46095 | AD36: 46086 | AE36: 4090180183 | AF36: 46095 | AG36: 46095 | AH36: 46095 | AI36: 141601 | AK36: 857.58
A37: CN 6360-29 | B37: 180184 | C37: LIBERADO | D37: EMITIDA | E37: 46084 | K37: ENFRIADA | L37: Paraguay | M37: TERRESTRE | N37: Los Andes | O37: PY23TMA1138 | Q37: TRANSMA | R37: ADRI003 | S37: ADRI002 | T37: WALMART | U37: =VLOOKUP('IMPO TERR'!T37,'Matriz datos'!$J$2:$K$10,2,0) -> AV. PDTE. EDUARDO FREI 8301, QUILICURA | V37: ALCIDES AVALOS | W37: CI 1.892.875 | X37: 0520260012345CDA | Y37: 0520260018836IIPA | Z37: 2605111953 | AA37: 2605112430 | AB37: 46088.67 | AC37: 46089 | AD37: 46087 | AE37: 4090180184 | AF37: 46090 | AG37: 46090.53 | AH37: 46092 | AI37: 141488 | AK37: 857.58
A38: AR/18899-1 | B38: 180186 | C38: LIBERADO | D38: PENDIENTE | E38: 46084 | K38: ENFRIADA | L38: Argentina | M38: TERRESTRE | N38: Los Andes | O38: 052AR219400891 | Q38: RIO COLORADO | R38: HDLX77 | S38: HGKX36 | T38: TOTTUS | U38: =VLOOKUP('IMPO TERR'!T38,'Matriz datos'!$J$2:$K$10,2,0) -> AV. AMERICO VESPUCIO 0350, QUILICURA | V38: DANIEL PEREZ | W38: DNI 41.031.050 | X38: 0520260012228CDA | Y38: 0520260018428IIPA | Z38: 2605110760 | AA38: 2605112514 | AB38: 46086.159 | AC38: 46087 | AD38: 46087 | AE38: 4090180186 | AF38: 46087 | AG38: 46087.775 | AH38: 46091 | AK38: 857.58
A39: SO/6362-3 | B39: 180188 | C39: LIBERADO | D39: EMITIDA | E39: 46084 | K39: CONGELADA | L39: Brasil | M39: TERRESTRE | N39: Los Andes | O39: BR453909370 | Q39: BRILHANTE | R39: RHR6J21 | S39: RLG5E30 | T39: WALMART | U39: =VLOOKUP('IMPO TERR'!T39,'Matriz datos'!$J$2:$K$10,2,0) -> AV. PDTE. EDUARDO FREI 8301, QUILICURA | V39: ADRIANO DE SOUZA | W39: CPF 440.436.603-59 | X39: 0520260011922CDA | Y39: 0520260019337IIPA | Z39: 2605108147 | AA39: 2605109858 | AB39: 46090 | AC39: 46091 | AD39: 46085 | AE39: 4090180188 | AF39: 46091 | AG39: 46091 | AH39: 46092 | AI39: 141540 | AK39: 857.58
A40: SO/6354-44 | B40: 180190 | C40: LIBERADO | D40: EMITIDA | E40: 46084 | K40: ENFRIADA | L40: Brasil | M40: TERRESTRE | N40: Los Andes | O40: BR547045035 | P40: 40933 | Q40: MARVEL | R40: SYU4C97 | S40: RYT3J70 | T40: WALMART | U40: =VLOOKUP('IMPO TERR'!T40,'Matriz datos'!$J$2:$K$10,2,0) -> AV. PDTE. EDUARDO FREI 8301, QUILICURA | V40: AMILTON SOARES SILVA | W40: CPF: 075.503.384-18 | X40: 0520260012239CDA | Y40: 0520260022045IIPA | Z40: 2605109742 | AA40: 2605110213 | AB40: 46096 | AC40: 46097 | AD40: 46086 | AE40: 4090180190 | AF40: 46097 | AG40: 46098 | AH40: 46098 | AI40: 141644 | AK40: 857.58
...

Sheet IMPO MAR
A1: Referencia de cliente. | B1: Número de despacho. | C1: ESTADO DE LA CARGA | D1: ETA | E1: INSTRUCCIÓN de DESCARGA | F1: Observaciones | G1: Confirmación de recepción de documentación (fecha correo) | H1: Indicación de si los documentos se encuentran OK o con observaciones. | I1: Fecha en que se solicitó modificación. | J1: Fecha en que se notificó. | K1: Fecha en que se recibieron correcciones. | L1: Fecha de nueva presentación, si corresponde. | M1: TIPO CARGA | N1: Origen de la carga. | O1: Tipo operacion | P1: PASO ADUANERO | Q1: factura comercial | R1: NAVE | S1: BL | T1: ALMACEN | U1: N° CONTENEDOR | V1: EMPRESA TRANSPORTE NACIONAL (BODEGA) | W1: PRONTO DESPACHO (FECHA SOLICITADO) | X1: CLIENTE FINAL | Y1: Dirección de descarga. DESTINO GD | Z1: Nombre chofer | AA1: N° IDENTIFICACION CHOFER | AB1: CDA SEREMI | AC1: Resolucion Sanitaria UYD | AD1: SAG | AE1: IIPA | AF1: Fecha de aceptacion DIN | AG1: DIN | AH1: COMPROBANTE PAGO TGR | AI1: Fecha de ingreso ALMACENISTA | AJ1: Fecha de presentación de documentos.(VISACIÓN) | AK1: Fecha de liberación - DESPACHADO | AL1: SELLO AGA | AM1: FACTURA AGENCIA | AN1: VALOR REMESA | AO1: T/C DOLAR legalizacion | AP1: T/C liberacion carga
A2: B/79127-2 | B2: 179630 | C2: LIBERADO | D2: 46087 | E2: 46093 | G2: 46072 | H2: ok | I2: ok | J2: - | K2: - | L2: - | M2: SECA - DRY | N2: Brasil | O2: MARITIMA | P2: San Antonio | Q2: B/79127-2 | R2: DUSSELDORF EXPRESS | S2: 721293763 | T2: CONTOPSA | U2: MRSU6552560 | V2: TAVI | W2: NO APLICA | X2: San Francisco del Mostazal 12.3 | Y2: San Francisco del Mostazal 12.3 | Z2: Cristian Alcaino | AA2: 13340077-K | AD2: 0520260011511CDA | AF2: 46091 | AG2: 4090179630 | AH2: 46091 | AI2: 46092 | AJ2: 46093 | AK2: 46093 | AN2: 5240000
A3: COL/7556-2 | B3: 180128 | C3: LIBERADO | D3: 46093 | E3: 46100 | G3: 46086 | H3: ok | I3: ok | J3: - | K3: - | L3: - | M3: ENFRIADA | N3: Colombia | O3: MARITIMA | P3: Valparaiso | Q3: ME-10756 | R3: MATTHEW SCHULTE | S3: BGA0513090 | T3: ZEAL | U3: SZLU5103010 | V3: VALPOTRANS | W3: NO APLICA | X3: CENCOSUD | Y3: SAN PABLO 11011, Pudahuel (cliente cencosud) | AB3: 2605110975 | AC3: 2613134243 | AD3: 0520260013509CDA | AF3: 46094 | AG3: 4090180128 | AH3: 46094 | AI3: 46097 | AJ3: 46099 | AK3: 46099 | AN3: 29000000
A4: B/79127-3 | B4: 180082 | C4: LIBERADO | D4: 46087 | E4: 46093 | G4: 46080 | H4: ok | I4: ok | J4: - | K4: - | L4: - | M4: SECA - DRY | N4: Brasil | O4: MARITIMA | P4: San Antonio | Q4: B/79127-3 | R4: DUSSELDORF EXPRESS | S4: 721315569 | T4: CONTOPSA | U4: BSIU8108703 | V4: TAVI | W4: NO APLICA | X4: San Francisco de Mostazal 19.3 | Y4: San Francisco de Mostazal 19.3 | Z4: Héctor Vilchez | AA4: 19069744-4 | AD4: 0520260012370CDA | AF4: 46090 | AG4: 4090180082 | AH4: 46091 | AI4: 46092 | AJ4: 46093 | AK4: 46093 | AN4: 5320000
A5: B/79127-4 | B5: 180352 | C5: EN TRANSITO | D5: 46109 | G5: 46091 | H5: lista de empaque | I5: 46094 | M5: SECA - DRY | N5: Brasil | O5: MARITIMA | P5: San Antonio | Q5: B/79127-4 | R5: MAERSK ACADIA | S5: 721336816 | T5: CONTOPSA | U5: MRKU5133782 | V5: TAVI | W5: NO APLICA | AG5: 4090180352
A6: B/79127-5 | B6: 180485 | C6: EN TRANSITO | D6: 46109 | G6: 46094 | M6: SECA - DRY | N6: Brasil | O6: MARITIMA | P6: San Antonio | Q6: B/79127-5 | R6: MAERSK ACADIA | S6: 721336818 | T6: CONTOPSA | U6: CAAU9115910 | V6: TAVI | W6: NO APLICA | AG6: 4090180485
A7: B/79127-6 | B7: 180487 | C7: EN TRANSITO | D7: 46109 | G7: 46094 | M7: SECA - DRY | N7: Brasil | O7: MARITIMA | P7: San Antonio | Q7: B/79127-6 | R7: MAERSK ACADIA | S7: 721359011 | T7: CONTOPSA | U7: MRKU5345333 | V7: TAVI | W7: NO APLICA | AG7: 4090180487
A8: B/79127-7 | B8: 180488 | C8: EN TRANSITO | D8: 46109 | G8: 46094 | M8: SECA - DRY | N8: Brasil | O8: MARITIMA | P8: San Antonio | Q8: B/79127-7 | R8: MAERSK ACADIA | S8: 721359010 | T8: CONTOPSA | U8: SUDU8788114 | V8: TAVI | W8: NO APLICA | AG8: 4090180488
A9: SO/6497-3 | B9: 180635 | C9: EN TRANSITO | D9: 46109 | M9: CONGELADA | N9: Brasil | O9: MARITIMA | P9: San Antonio | Q9: SO/6497-3 | R9: MAERSK ACADIA | S9: 721354315 | T9: CONTOPSA | U9: MNBU3476210 | W9: 46101 | X9: ICESTAR | Y9: AVENIDA AMERICO VESPUCIO N°0350,QUILICURA | AB9: 2605142642 | AG9: 4090180635
A10: B/79127-8 | B10: 180675 | C10: EN TRANSITO | D10: 46116 | M10: SECA - DRY | N10: Brasil | O10: MARITIMA | P10: San Antonio | Q10: B/79127-8 | R10: MALIAKOS | S10: 721316057 | T10: CONTOPSA | U10: MRSU5173047 | V10: TAVI | W10: NO APLICA | AG10: 4090180675
A11: B/79127-9 | B11: 180676 | C11: EN TRANSITO | D11: 46116 | M11: SECA - DRY | N11: Brasil | O11: MARITIMA | P11: San Antonio | Q11: B/79127-9 | R11: MALIAKOS | S11: 721347390 | T11: CONTOPSA | U11: MRKU6316026 | V11: TAVI | W11: NO APLICA | AG11: 4090180676
B90: 179630 (MARITIMA) | C90: EN ALMACEN | E90: PENDIENTE | N90: Brasil | O90: MARITIMA | P90: San Antonio | Q90: B/79127-2 | S90: 721293763
B91: 180128 (MARITIMA) | C91: EN TRANSITO | E91: PENDIENTE | N91: Colombia | O91: MARITIMA | P91: San Antonio | Q91: ME-10756 | S91: BGA0513090
B92: 180082 (MARITIMA) | C92: EN ALMACEN | E92: PENDIENTE | N92: Brasil | O92: MARITIMA | P92: San Antonio | Q92: B/79127-3 | S92: 721315569
B93: 180352 (MARITIMA) | C93: EN TRANSITO | E93: PENDIENTE | N93: Brasil | O93: MARITIMA | P93: San Antonio | Q93: B/79127-4 | S93: 721336816
E125: PENDIENTE
E126: PENDIENTE
E127: PENDIENTE
E128: PENDIENTE
E129: PENDIENTE
E130: PENDIENTE
E131: PENDIENTE
E132: PENDIENTE
E133: PENDIENTE
E134: PENDIENTE
E135: PENDIENTE
E136: PENDIENTE
... E143: PENDIENTE

Sheet Hoja1

Sheet IMPO AEREA
A1: Referencia de cliente. | B1: Número de despacho. | C1: ESTADO DE LA CARGA | D1: Confirmación de recepción de documentación (fecha correo) | E1: Indicación de si los documentos se encuentran OK o con observaciones. | F1: Fecha en que se solicitó modificación. | G1: Fecha en que se notificó. | H1: Fecha en que se recibieron correcciones. | I1: Fecha de nueva presentación, si corresponde. | J1: TIPO CARGA | K1: Origen de la carga. | L1: Tipo operacion | M1: Paso aduanero | N1: factura comercial | O1: AWL / GUIA AEREA | P1: ALMACEN | Q1: EMISOR GUIA AEREA | R1: EMPRESA TRANSPORTE NACIONAL (BODEGA) | S1: CLIENTE FINAL | T1: Dirección de descarga. DESTINO GD | U1: Nombre chofer | V1: N° IDENTIFICACION CHOFER | W1: CDA SEREMI | X1: Resolucion Sanitaria UYD | Y1: SAG | Z1: IIPA | AA1: Fecha de aceptacion DIN | AB1: DIN | AC1: COMPROBANTE PAGO TGR | AD1: Fecha de ingreso ALMACENISTA | AE1: Fecha de presentación de documentos.(VISACIÓN) | AF1: Fecha de liberación - DESPACHADO | AG1: SELLO AGA | AH1: FACTURA AGENCIA | AI1: VALOR REMESA | AJ1: T/C DOLAR legalizacion | AK1: T/C liberacion carga
A2: S-79335 | B2: 180447 | C2: PENDIENTE | D2: 46093 | J2: CONGELADA | K2: Brasil | L2: AEREO | M2: METROPOLITANA | O2: 54943191131 | Q2: ABSA AEROLINHAS BRASILEIRAS | W2: 2613127706 | X2: PEND | Y2: 1320260001388CDA | AA2: 46098 | AB2: 4090180447 | AC2: 46099 | AI2: 2000000
A3: S-79335A | B3: 180447 | C3: PENDIENTE | D3: 46093 | J3: CONGELADA | K3: Brasil | L3: AEREO | M3: METROPOLITANA | O3: 54943191131 | Q3: ABSA AEROLINHAS BRASILEIRAS | W3: 2613127706 | X3: PEND | Y3: 1320260001388CDA | AA3: 46098 | AB3: 4090180447 | AC3: 46099 | AI3: 2000000

Sheet Matriz datos
A1: ESTADO DE OPERACION | B1: CARGA | C1: TIPO CARGA | D1: TIPO OPERACION | E1: TIPO TRAMITE | G1: INSRUCCION DESCARGA | I1: OBSERVACION DOCUMENTAL | J1: cliente | K1: direccion
A2: EN CURSO | B2: EN TRANSITO | C2: CONGELADA | D2: AEREA | E2: CDA | F2: carga en viaje a puerto | G2: PENDIENTE | H2: PRESENTACIÓN SAG OBJETADA | I2: CORREGIR documentos | J2: ALMAFRIGO | K2: AV. GALVARINO 8601 BGA. 11, QUILICURA
A3: FINALIZADA | B3: ARRIBADA EN PUERTO | C3: ENFRIADA | D3: TERRESTRE | E3: UYD | F3: carga ingresa a puerto | G3: GUIA DESPACHO EMITIDA | H3: PRESENTACIÓN SEREMI OBJETADA | I3: Documentos pendientes | J3: CIAL | K3: CAMINO SANTA MARTA 2101, MAIPU
A4: URGENTE | B4: EN ALMACEN | C4: SECA - DRY | D4: MARITIMA | E4: IIPA | F4: boleta emitida/ carga ingresa a Ext Contopsa | H4: PRESENTACION SAG - SEREMI OBJETADA | I4: Documentos OK | J4: WALMART | K4: AV. PDTE. EDUARDO FREI 8301, QUILICURA
B5: DESPACHADO | F5: espera instrucciones descarga | J5: ICESTAR | K5: AV. AMERICO VESPUCIO 0350, QUILICURA
B6: LIBERADO | J6: RAMIREZ | K6: AV. EL PARRON 345, LA CISTERNA
J7: TOTTUS | K7: AV. AMERICO VESPUCIO 0350, QUILICURA
J8: RENDIC | K8: CAMINO LO AGUIRRE SUR 537, PUDAHUEL
J9: KARMAC | K9: CORDILLERA 451, QUILICURA
J10: FRIGOZETA | K10: 6 ORIENTE 152-D CALETERA ORIENTE ALTURA KM 39, PAINE
