Workbook
Name CARGA: #REF!
Name cliente: #REF!
Name INSTRUCCIONES: #REF!
Name TIPO_CARGA: #REF!
Name TIPO_OPERACION: #REF!
Name TIPO_TRAMITE: #REF!

Sheet IMPO TERR
A1: Referencia cliente. | B1: Número de despacho. | C1: ESTADO DE LA CARGA | D1: INSTRUCCIÓN de DESCARGA | E1: Recepción de documentación (FECHA) | F1: CONDICION DOCUMENTAL | G1: Observaciones | H1: Fecha: MODIFICACION SOLICITADA | I1: CORRECCIONES RECEPCIONADAS | J1: FACTURA COMERCIAL | K1: TIPO CARGA | L1: Origen de la carga. | M1: Tipo operacion | N1: Paso aduanero (cuando corresponda). | O1: CONOCIMIENTO EMBARQUE / CRT | P1: MIC | Q1: EMPRESA DE TRANSPORTE | R1: Patente del camión (TRACTO) | S1: Patente del camión (REMOLQUE) | T1: CLIENTE FINAL | U1: Dirección de descarga. DESTINO GD | V1: Nombre chofer | W1: N° IDENTIFICACION | X1: Fecha de ingreso ALMACENISTA | Y1: FECHA PAPELETA INGRESO | Z1: Fecha de aceptacion DIN | AA1: DIN | AB1: COMPROBANTE PAGO TGR | AC1: Fecha de presentación de documentos.( DESPACHO) | AD1: Fecha de liberación.( SALIDA DE ALMACEN) | AE1: SELLO AGA | AF1: REMESA | AG1: T/C DOLAR legalizacion | AH1: T/C liberacion carga
A2: O/87250-6 | B2: 179930 | C2: LIBERADO | D2: EMITIDA | E2: 46076 | F2: ok | G2: Solo envio de doctos draft | H2: 46078 | I2: 05/03/2026 09:35 hrs | K2: ENFRIADA | L2: Brasil | M2: TERRESTRE | N2: Los Andes | O2: BR547044923 | P2: 33737 | Q2: MARVEL | R2: SWY2C62 | S2: RYP8I48 | T2: ALMAFRIGO | U2: =VLOOKUP('IMPO TERR'!T2,#REF!,2,0) -> #REF! | V2: FABRICIO ESTEVAO DA CRUZ | W2: CPF: 445.947.978-81 | X2: 46083.86 | Y2: 46084 | Z2: 46087 | AA2: 4090179930 | AB2: 46087.726 | AC2: 46090.479 | AD2: 46090.56 | AF2: 25010000 | AG2: 0 | AH2: 0
A3: CN 6526-1 | B3: 179947 | C3: LIBERADO | D3: PENDIENTE | E3: 46076 | G3: En espera de resolucion de bodega (minerva) | K3: CONGELADA | L3: Paraguay | M3: TERRESTRE | N3: Los Andes | O3: PY23TMA1134 | P3: 32028 | Q3: TRANSMA | R3: AALJ416 | S3: AALJ421 | T3: CIAL | U3: =VLOOKUP('IMPO TERR'!T3,#REF!,2,0) -> #REF! | V3: JUAN PABLO MORINIGO | W3: CI: 3564133 | X3: 46080.908 | Y3: 46081 | Z3: 46085 | AA3: 4090179947 | AB3: 46085.553 | AC3: 46086.655 | AD3: 46093 | AF3: 6500000 | AG3: 857.58
A4: SO/6370-22 | B4: 179972 | C4: LIBERADO | D4: PENDIENTE | E4: 46077 | F4: DOCS ORIGINALES PENDIENTES | G4: DOCS ORIGINALES PENDIENTES | K4: ENFRIADA | L4: Brasil | M4: TERRESTRE | N4: Los Andes | O4: BR547044933 | P4: 32413 | Q4: MARVEL | R4: RXM4D24 | S4: RLL3F14 | T4: WALMART | U4: =VLOOKUP('IMPO TERR'!T4,#REF!,2,0) -> #REF! | V4: MARCOS ANTONIO DO CARMO | W4: CPF: 068.976.759-54 | X4: 46082.479 | Y4: 46083 | Z4: 46085 | AA4: 4090179972 | AB4: 46085.653 | AC4: 46085.753 | AD4: 46085.833 | AF4: 25950000 | AG4: 857.58
A5: SO/6370-23 | B5: 180001 | C5: LIBERADO | D5: PENDIENTE | E5: 46077 | K5: ENFRIADA | L5: Brasil | M5: TERRESTRE | N5: Los Andes | O5: BR547044931 | Q5: MARVEL | R5: RXY9C34 | S5: RXW9H24 | T5: WALMART | U5: =VLOOKUP('IMPO TERR'!T5,#REF!,2,0) -> #REF! | V5: IVAN DOS SANTOS | W5: CPF: 096.316.418-05 | X5: 46086.792 | Y5: 46087 | Z5: 46079 | AA5: 4090180001 | AB5: 46087 | AC5: 46087.775 | AD5: 46087.826 | AF5: 26010000 | AG5: 857.95
A6: SO/6370-26 | B6: 180023 | C6: LIBERADO | D6: PENDIENTE | E6: 46078 | K6: ENFRIADA | L6: Brasil | M6: TERRESTRE | N6: Los Andes | O6: BR547044941 | P6: 34269 | Q6: MARVEL | R6: QJG8563 | S6: SXW7I81 | T6: WALMART | U6: =VLOOKUP('IMPO TERR'!T6,#REF!,2,0) -> #REF! | V6: WESLEM DO NASCIMENTO | W6: CPF: 042.438.270-95 | X6: 46084.791 | Y6: 46085 | Z6: 46080 | AA6: 4090180023 | AB6: 46085 | AC6: 46084.791 | AD6: 46085.734 | AF6: 25520000 | AG6: 857.95
A7: CN 25221 | B7: 180040 | C7: LIBERADO | D7: PENDIENTE | E7: 46078 | K7: ENFRIADA | L7: Paraguay | M7: TERRESTRE | N7: Los Andes | O7: 2026PYSANJOSE044 | Q7: SAN JOSE | R7: TISJ001 | S7: TISJ004 | T7: ICESTAR | U7: =VLOOKUP('IMPO TERR'!T7,#REF!,2,0) -> #REF! | V7: HUGO ARIEL MORINIGO | W7: CI: 5.497.180 | X7: 46082.751 | Y7: 46083 | Z7: 46084 | AA7: 4090180040 | AB7: 46084 | AC7: 46085.669 | AD7: 46087.305 | AF7: 28670000 | AG7: 857.58
A8: SO/6360-28 | B8: 180056 | C8: LIBERADO | D8: PENDIENTE | E8: 46079 | K8: ENFRIADA | L8: Brasil | M8: TERRESTRE | N8: Los Andes | O8: BR547044939 | Q8: MARVEL | R8: RXQ0G36 | S8: RYK0I89 | T8: WALMART | U8: =VLOOKUP('IMPO TERR'!T8,#REF!,2,0) -> #REF! | V8: EEDISON JORGE NUNES | X8: 46086.866 | Y8: 46087 | Z8: 46083 | AA8: 4090180056 | AB8: 46087 | AC8: 46087.779 | AD8: 46087.824 | AF8: 25880000 | AG8: 857.58
A9: SO/6360-25 | B9: 180057 | C9: LIBERADO | D9: PENDIENTE | E9: 46079 | F9: C.O. ERROR | G9: C.O. ERROR | K9: ENFRIADA | L9: Brasil | M9: TERRESTRE | N9: Los Andes | O9: BR547044872 | P9: 32539 | Q9: MARVEL | R9: TDX0H19 | S9: SXM2B63 | T9: WALMART | U9: =VLOOKUP('IMPO TERR'!T9,#REF!,2,0) -> #REF! | V9: ANDRE LUIZ DE AQUINO SOARES | W9: CPF: 932.708.872-72 | X9: 46082.639 | Y9: 46083 | Z9: 46084 | AA9: 4090180057 | AB9: 46084 | AC9: 46085.596 | AD9: 46085.68 | AF9: 25770000 | AG9: 857.58
A10: SO/6356-4 | B10: 180059 | C10: LIBERADO | D10: PENDIENTE | E10: 46079 | K10: CONGELADA | L10: Brasil | M10: TERRESTRE | N10: Los Andes | O10: BR453909363 | Q10: BRILHANTE | R10: RHG9B61 | S10: RLA8I71 | T10: WALMART | U10: =VLOOKUP('IMPO TERR'!T10,#REF!,2,0) -> #REF! | X10: 46087.03 | Y10: 46087 | Z10: 46083 | AA10: 4090180059 | AB10: 46087 | AC10: 46088.481 | AD10: 46088.604 | AF10: 25720000 | AG10: 857.58
A11: O/87304-3 | B11: 180066 | C11: LIBERADO | D11: EMITIDA | E11: 46079 | K11: ENFRIADA | L11: Brasil | M11: TERRESTRE | N11: Los Andes | O11: BR261615121 | Q11: BELMAT | R11: GHG7D55 | S11: RLB4D02 | T11: ICESTAR | U11: =VLOOKUP('IMPO TERR'!T11,#REF!,2,0) -> #REF! | V11: MARCELO DINIZ | X11: 46089.87 | Y11: 46090 | Z11: 46085 | AA11: 4090180066 | AB11: 46090 | AC11: 46091 | AD11: 46092 | AE11: 141542 | AF11: 25180000 | AG11: 857.58
A12: SO/6356-5 | B12: 180067 | C12: LIBERADO | D12: EMITIDA | E12: 46079 | F12: C.O. ERROR | G12: C.O. ERROR | K12: CONGELADA | L12: Brasil | M12: TERRESTRE | N12: Los Andes | O12: BR168811718 | R12: RLB6G92 | S12: MFV6036 | T12: WALMART | U12: =VLOOKUP('IMPO TERR'!T12,#REF!,2,0) -> #REF! | V12: HENRIQUE CORREIA | X12: 46089.755 | Y12: 09-03-2026 | Z12: 46083 | AA12: 4090180067 | AB12: 46090 | AC12: 46090.659 | AD12: 46090 | AE12: 141496 | AF12: 24360000 | AG12: 857.58
A13: CN 6357-10 | B13: 180070 | C13: LIBERADO | D13: PENDIENTE | E13: 46079 | K13: ENFRIADA | L13: Paraguay | M13: TERRESTRE | N13: Los Andes | O13: 2026PYSANJOSE049 | Q13: SAN JOSE | R13: LJWL11 | S13: KDHS40 | T13: WALMART | U13: =VLOOKUP('IMPO TERR'!T13,#REF!,2,0) -> #REF! | X13: 46083.877 | Y13: 46084 | Z13: 46085 | AA13: 4090180070 | AB13: 46085 | AC13: 46085.771 | AD13: 46087.752 | AF13: 27110000 | AG13: 857.58
A14: CN 6358-10 | B14: 180072 | C14: LIBERADO | D14: PENDIENTE | E14: 46079 | K14: ENFRIADA | L14: Paraguay | M14: TERRESTRE | N14: Los Andes | O14: 26PYFOODS314 | Q14: FRIGOMERC | R14: AAAE804 | S14: AAAE476 | T14: WALMART | U14: =VLOOKUP('IMPO TERR'!T14,#REF!,2,0) -> #REF! | X14: 46084.793 | Y14: 46085 | Z14: 46085 | AA14: 4090180072 | AB14: 46085 | AC14: 46085.748 | AD14: 46091 | AF14: 26210000 | AG14: 857.58
A15: CN 6359-8 | B15: 180073 | C15: LIBERADO | D15: PENDIENTE | E15: 46079 | K15: ENFRIADA | L15: Paraguay | M15: TERRESTRE | N15: Los Andes | O15: PYLG066/2026 | P15: 2026 | Q15: LUCERY | R15: AAGN977 | S15: AAAE634 | T15: WALMART | U15: =VLOOKUP('IMPO TERR'!T15,#REF!,2,0) -> #REF! | X15: 46084.768 | Y15: 46085 | Z15: 46083 | AA15: 4090180073 | AB15: 46085 | AC15: 46085.597 | AD15: 46087.81 | AF15: 25670000 | AG15: 857.58
A16: SO/6354-43 | B16: 180074 | C16: LIBERADO | D16: PENDIENTE | E16: 46079 | F16: C.O. VALIDAR | G16: C.O. VALIDAR | K16: ENFRIADA | L16: Brasil | M16: TERRESTRE | N16: Los Andes | O16: BR547044989 | Q16: MARVEL | R16: JBG8A84 | S16: RYM5E22 | T16: WALMART | U16: =VLOOKUP('IMPO TERR'!T16,#REF!,2,0) -> #REF! | X16: 46087.571 | Y16: 46088 | Z16: 46084 | AA16: 4090180074 | AB16: 46087 | AC16: 46088.563 | AD16: 46088.638 | AF16: 24850000 | AG16: 857.58
A17: SO/6354-37 | B17: 180075 | C17: LIBERADO | D17: EMITIDA | E17: 46079 | K17: ENFRIADA | L17: Brasil | M17: TERRESTRE | N17: Los Andes | O17: BR547044911 | R17: RYB8I87 | S17: RYB8I87 | T17: WALMART | U17: =VLOOKUP('IMPO TERR'!T17,#REF!,2,0) -> #REF! | V17: ALESSANDRO VIEIRA | X17: 46087.645 | Y17: 46087 | Z17: 46083 | AA17: 4090180075 | AB17: 46087 | AC17: 46090.481 | AD17: 46090.546 | AF17: 23250000 | AG17: 857.58
A18: CN 25320-6 | B18: 180109 | C18: LIBERADO | D18: PENDIENTE | E18: 46080 | K18: ENFRIADA | L18: Paraguay | M18: TERRESTRE | N18: Los Andes | O18: PYLG070/2026 | P18: 2026 | Q18: LUCERY | R18: AAHI130 | S18: AAKB750 | T18: RAMIREZ | U18: =VLOOKUP('IMPO TERR'!T18,#REF!,2,0) -> #REF! | X18: 46087.402 | Y18: 46087 | Z18: 46084 | AA18: 4090180109 | AB18: 46087 | AC18: 46087.778 | AD18: 46091 | AF18: 28760000 | AG18: 857.58
A19: SO/6354-41 | B19: 180110 | C19: LIBERADO | D19: PENDIENTE | E19: 46080 | K19: ENFRIADA | L19: Brasil | M19: TERRESTRE | N19: Los Andes | O19: BR547044956 | Q19: MARVEL | R19: RYX9E71 | S19: RYP2J71 | T19: WALMART | U19: =VLOOKUP('IMPO TERR'!T19,#REF!,2,0) -> #REF! | X19: 46086.751 | Y19: 46087 | Z19: 46085 | AA19: 4090180110 | AB19: 46087 | AC19: 46087.745 | AD19: 46087.808 | AF19: 24290000 | AG19: 857.58
A20: O/87315-2 | B20: 180112 | C20: LIBERADO | D20: PENDIENTE | E20: 46080 | K20: ENFRIADA | L20: Brasil | M20: TERRESTRE | N20: Los Andes | O20: BR547044967 | Q20: MARVEL | R20: RXT9I23 | S20: RXO5E92 | T20: ICESTAR | U20: =VLOOKUP('IMPO TERR'!T20,#REF!,2,0) -> #REF! | X20: 46087.459 | Y20: 46087 | Z20: 46085 | AA20: 4090180112 | AB20: 46087 | AC20: 46087.788 | AD20: 46088.512 | AF20: 25920000 | AG20: 857.58
A21: O/87568 | B21: 180114 | C21: LIBERADO | D21: PENDIENTE | E21: 46080 | K21: CONGELADA | L21: Brasil | M21: TERRESTRE | N21: Los Andes | O21: BR698100492 | Q21: VIZZOTTO | R21: RYC0I37 | S21: RLI0I42 | T21: RAMIREZ | U21: =VLOOKUP('IMPO TERR'!T21,#REF!,2,0) -> #REF! | X21: 46087.439 | Y21: 46087 | Z21: 46085 | AA21: 4090180114 | AB21: 46087 | AC21: 46087.777 | AD21: 46088.412 | AF21: 25840000 | AG21: 857.58
A22: CN 6360-30 | B22: 180115 | C22: LIBERADO | D22: EMITIDA | E22: 46080 | K22: ENFRIADA | L22: Paraguay | M22: TERRESTRE | N22: Los Andes | O22: PYLG072/2026 | P22: 2026 | Q22: LUCERY | R22: AAIE199 | S22: AAMA137 | T22: WALMART | U22: =VLOOKUP('IMPO TERR'!T22,#REF!,2,0) -> #REF! | V22: FERNANDO ACOSTA AGUILAR | X22: 46088.769 | Y22: 08-03-2026 | Z22: 46084 | AA22: 4090180115 | AB22: 46090 | AC22: 46090.528 | AD22: 46092 | AE22: 141491 | AF22: 25470000 | AG22: 857.58
A23: SO/6397-2P | B23: 180133 | C23: LIBERADO | D23: EMITIDA | E23: 46083 | G23: GUIA MOD.DESTINO (RUTA 5 SUR N 2786 KM252-PLANTA 3, TALCA) | K23: CONGELADA | L23: Brasil | M23: TERRESTRE | N23: Los Andes | O23: BR707400447 | Q23: MF | R23: SQA4B99 | S23: SPZ5D39 | T23: ICESTAR | U23: Ruta 5 Sur N 2786 KM 252-Planta 3, Talca | V23: JACSON DOUGLAS LOCH | X23: 46089.864 | Y23: 46090 | Z23: 46085 | AA23: 4090180133 | AB23: 46090 | AC23: 46090 | AD23: 46090 | AE23: 141489 | AF23: 16870000 | AG23: 857.58
A24: SO/6456-3 | B24: 180136 | C24: LIBERADO | D24: PENDIENTE | E24: 46083 | K24: CONGELADA | L24: Brasil | M24: TERRESTRE | N24: Los Andes | O24: BR512203456 | Q24: VENEZA | R24: RGM7C35 | S24: QJB2B11 | T24: ICESTAR | U24: =VLOOKUP('IMPO TERR'!T24,#REF!,2,0) -> #REF! | X24: 46086.938 | Y24: 46087 | Z24: 46086 | AA24: 4090180136 | AB24: 46087 | AC24: 46087.777 | AD24: 46088.446 | AF24: 25980000 | AG24: 857.58
A25: SO/6354-39 | B25: 180137 | C25: LIBERADO | D25: PENDIENTE | E25: 46083 | K25: ENFRIADA | L25: Brasil | M25: TERRESTRE | N25: Los Andes | O25: BR547044938 | P25: 32433 | Q25: MARVEL | R25: SXA9J22 | S25: SXA1F12 | T25: WALMART | U25: =VLOOKUP('IMPO TERR'!T25,#REF!,2,0) -> #REF! | X25: 46082.575 | Y25: 02-03-2026 | Z25: 46085 | AA25: 4090180137 | AB25: 46085 | AC25: 46085.756 | AD25: 46085.835 | AF25: 24410000 | AG25: 857.58
A26: SO/6370-27 | B26: 180139 | C26: LIBERADO | D26: EMITIDA | E26: 46083 | K26: ENFRIADA | L26: Brasil | M26: TERRESTRE | N26: Los Andes | O26: BR547044995 | Q26: MARVEL | R26: RLI5A86 | S26: RYF1C29 | T26: WALMART | U26: =VLOOKUP('IMPO TERR'!T26,#REF!,2,0) -> #REF! | V26: STEVAO GARCIA | X26: 46089.475 | Y26: 46090 | Z26: 46086 | AA26: 4090180139 | AB26: 46090 | AC26: 46090 | AD26: 46091 | AE26: 141504 | AF26: 25980000 | AG26: 857.58
A27: SO/6354-42 | B27: 180145 | C27: LIBERADO | D27: PENDIENTE | E27: 46083 | K27: ENFRIADA | L27: Brasil | M27: TERRESTRE | N27: Los Andes | O27: BR547044969 | Q27: MARVEL | R27: QTL0655 | S27: RYL9J02 | T27: WALMART | U27: =VLOOKUP('IMPO TERR'!T27,#REF!,2,0) -> #REF! | X27: 46087.548 | Y27: 46088 | Z27: 46086 | AA27: 4090180145 | AB27: 46088 | AC27: 46088.562 | AD27: 46088.651 | AF27: 24010000 | AG27: 857.58
A28: SO/6331-15 | B28: 180146 | C28: LIBERADO | D28: PENDIENTE | E28: 46083 | K28: ENFRIADA | L28: Argentina | M28: TERRESTRE | N28: Los Andes | O28: 052024TC2026 | Q28: TRES CRUCES | R28: AG826IT | S28: AG337WM | T28: WALMART | U28: =VLOOKUP('IMPO TERR'!T28,#REF!,2,0) -> #REF! | X28: 46084.56 | Y28: 46085 | Z28: 46086 | AA28: 4090180146 | AB28: 46086 | AC28: 46086.739 | AD28: 46086.837 | AG28: 857.58
A29: SO/6330-11 | B29: 180147 | C29: LIBERADO | D29: PENDIENTE | E29: 46083 | K29: ENFRIADA | L29: Argentina | M29: TERRESTRE | N29: Los Andes | O29: 052AR219400890 | Q29: RIO COLORADO | R29: RBTW67 | S29: JB6491 | T29: WALMART | U29: =VLOOKUP('IMPO TERR'!T29,#REF!,2,0) -> #REF! | X29: 46084.081 | Y29: 46084 | Z29: 46085 | AA29: 4090180147 | AB29: 46085 | AC29: 46085.672 | AD29: 46088.468 | AG29: 857.58
A30: SO/6354-38 | B30: 180152 | C30: LIBERADO | D30: EMITIDA | E30: 46083 | K30: ENFRIADA | L30: Brasil | M30: TERRESTRE | N30: Los Andes | O30: BR547044953 | Q30: MARVEL | R30: RDS0192 | S30: TPY4177 | T30: WALMART | U30: =VLOOKUP('IMPO TERR'!T30,#REF!,2,0) -> #REF! | V30: JOAO CARLOS ALVES | W30: CPF: 714.674.756-53 | X30: 46091 | Y30: 46092 | Z30: 46086 | AA30: 4090180152 | AB30: 46091 | AC30: 46092 | AD30: 46092 | AE30: 141548 | AG30: 857.58
A31: O/87772-1 | B31: 180153 | C31: LIBERADO | D31: PENDIENTE | E31: 46083 | K31: CONGELADA | L31: Brasil | M31: TERRESTRE | N31: Los Andes | O31: BR547044927 | Q31: MARVEL | R31: RLM6H97 | S31: QIT8604 | T31: ICESTAR | U31: =VLOOKUP('IMPO TERR'!T31,#REF!,2,0) -> #REF! | X31: 46087.731 | Y31: 46088 | Z31: 46085 | AA31: 4090180153 | AB31: 46088 | AC31: 46088.574 | AD31: 46088.648 | AG31: 857.58
A32: O/87772-2 | B32: 180154 | C32: LIBERADO | D32: EMITIDA | E32: 46083 | K32: CONGELADA | L32: Brasil | M32: TERRESTRE | N32: Los Andes | O32: BR547045030 | Q32: MARVEL | R32: TDQ9I41 | S32: SXV1F31 | T32: ICESTAR | U32: =VLOOKUP('IMPO TERR'!T32,#REF!,2,0) -> #REF! | V32: JOSE PAGOTTI | X32: 46089.969 | Y32: 46090 | Z32: 46086 | AA32: 4090180154 | AB32: 46090 | AC32: 46090 | AD32: 46090 | AE32: 141505 | AG32: 857.58
A33: SO/6360-31 | B33: 180178 | C33: LIBERADO | D33: EMITIDA | E33: 46084 | K33: ENFRIADA | L33: Brasil | M33: TERRESTRE | N33: Los Andes | O33: BR547045033 | Q33: MARVEL | R33: RXZ4F56 | S33: RYC8F45 | T33: WALMART | U33: =VLOOKUP('IMPO TERR'!T33,#REF!,2,0) -> #REF! | V33: ALEX SANDRO GARCEZ AMARO | W33: CPF: 012.846.590-54 | X33: 46091 | Y33: 46092 | Z33: 46087 | AA33: 4090180178 | AB33: 46091 | AC33: 46092 | AD33: 46092 | AE33: 141553 | AG33: 857.58
A34: SO/6354-45 | B34: 180180 | C34: LIBERADO | D34: EMITIDA | E34: 46084 | K34: ENFRIADA | L34: Brasil | M34: TERRESTRE | N34: Los Andes | O34: BR547045016 | Q34: MARVEL | R34: RXY9E54 | S34: RXK1C65 | T34: WALMART | U34: =VLOOKUP('IMPO TERR'!T34,#REF!,2,0) -> #REF! | V34: MARCIO DA SILVA | X34: 46090.494 | Y34: 46091 | Z34: 46086 | AA34: 4090180180 | AB34: 46090 | AC34: 46091 | AD34: 46091 | AE34: 141522 | AG34: 857.58
A35: SO/6370-29 | B35: 180181 | C35: LIBERADO | D35: EMITIDA | E35: 46084 | K35: ENFRIADA | L35: Brasil | M35: TERRESTRE | N35: Los Andes | O35: BR547045026 | Q35: MARVEL | R35: SXI7A02 | S35: RYW5J12 | T35: WALMART | U35: =VLOOKUP('IMPO TERR'!T35,#REF!,2,0) -> #REF! | V35: ELIO PEREIRA DE OLIVEIRA | X35: 46090 | Y35: 46091 | Z35: 46086 | AA35: 4090180181 | AB35: 46091 | AC35: 46091 | AD35: 46091 | AE35: 141526 | AG35: 857.58
A36: SO/6354-46 | B36: 180183 | C36: LIBERADO | D36: EMITIDA | E36: 46084 | K36: ENFRIADA | L36: Brasil | M36: TERRESTRE | N36: Los Andes | O36: BR547045038 | P36: 40365 | Q36: MARVEL | R36: RXW2G34 | S36: SXA7D71 | T36: WALMART | U36: =VLOOKUP('IMPO TERR'!T36,#REF!,2,0) -> #REF! | V36: GABRIEL CAMARGO FORTES | W36: CPF:446.710.208-66 | X36: 46094 | Y36: 46095 | Z36: 46086 | AA36: 4090180183 | AC36: 46095 | AD36: 46095 | AE36: 141601 | AG36: 857.58
A37: CN 6360-29 | B37: 180184 | C37: LIBERADO | D37: EMITIDA | E37: 46084 | K37: ENFRIADA | L37: Paraguay | M37: TERRESTRE | N37: Los Andes | O37: PY23TMA1138 | Q37: TRANSMA | R37: ADRI003 | S37: ADRI002 | T37: WALMART | U37: =VLOOKUP('IMPO TERR'!T37,#REF!,2,0) -> #REF! | V37: ALCIDES AVALOS | X37: 46088.67 | Y37: 46089 | Z37: 46087 | AA37: 4090180184 | AB37: 46090 | AC37: 46090.53 | AD37: 46092 | AE37: 141488 | AG37: 857.58
A38: AR/18899-1 | B38: 180186 | C38: LIBERADO | D38: PENDIENTE | E38: 46084 | K38: ENFRIADA | L38: Argentina | M38: TERRESTRE | N38: Los Andes | O38: 052AR219400891 | Q38: RIO COLORADO | R38: HDLX77 | S38: HGKX36 | T38: TOTTUS | U38: =VLOOKUP('IMPO TERR'!T38,#REF!,2,0) -> #REF! | X38: 46086.159 | Y38: 46087 | Z38: 46087 | AA38: 4090180186 | AB38: 46087 | AC38: 46087.775 | AD38: 46091 | AG38: 857.58
A39: SO/6362-3 | B39: 180188 | C39: LIBERADO | D39: EMITIDA | E39: 46084 | K39: CONGELADA | L39: Brasil | M39: TERRESTRE | N39: Los Andes | O39: BR453909370 | Q39: BRILHANTE | R39: RHR6J21 | S39: RLG5E30 | T39: WALMART | U39: =VLOOKUP('IMPO TERR'!T39,#REF!,2,0) -> #REF! | V39: ADRIANO DE SOUZA | X39: 46090 | Y39: 46091 | Z39: 46085 | AA39: 4090180188 | AB39: 46091 | AC39: 46091 | AD39: 46092 | AE39: 141540 | AG39: 857.58
A40: SO/6354-44 | B40: 180190 | C40: LIBERADO | D40: EMITIDA | E40: 46084 | K40: ENFRIADA | L40: Brasil | M40: TERRESTRE | N40: Los Andes | O40: BR547045035 | P40: 40933 | Q40: MARVEL | R40: SYU4C97 | S40: RYT3J70 | T40: WALMART | U40: =VLOOKUP('IMPO TERR'!T40,#REF!,2,0) -> #REF! | V40: AMILTON SOARES SILVA | W40: CPF: 075.503.384-18 | X40: 46096 | Y40: 46097 | Z40: 46086 | AA40: 4090180190 | AB40: 46097 | AC40: 46098 | AD40: 46098 | AE40: 141644 | AG40: 857.58
...

Sheet CERTIFICACIONES
A1: REF. CLIENTE | B1: DESPACHO | C1: FECHA PRESENTACION | D1: TIPO TRAMITE | E1: ENTIDAD | F1: DOCUMENTO | G1: ADUANA | H1: ESTADO | I1: OBSERVACIONES
A2: O/87250-6 | B2: 179930 | D2: CDA | E2: SEREMI | F2: 2605113227 | G2: LOS ANDES
A3: O/87250-6 | B3: 179930 | D3: UYD | E3: SEREMI | F3: 2605114532 | G3: LOS ANDES
A4: O/87250-6 | B4: 179930 | D4: CDA | E4: SAG | F4: 0520260012446CDA | G4: LOS ANDES
A5: O/87250-6 | B5: 179930 | D5: IIPA | E5: SAG | F5: 0520260018764IIPA | G5: LOS ANDES
A6: CN 6526-1 | B6: 179947 | D6: CDA | E6: SEREMI | F6: 2605101385 | G6: LOS ANDES
A7: CN 6526-1 | B7: 179947 | D7: UYD | E7: SEREMI | F7: 2605109992 | G7: LOS ANDES
A8: CN 6526-1 | B8: 179947 | D8: CDA | E8: SAG | F8: 0520260011071CDA | G8: LOS ANDES
A9: SO/6370-22 | B9: 179972 | D9: CDA | E9: SEREMI | F9: 2605106362 | G9: LOS ANDES
A10: SO/6370-22 | B10: 179972 | D10: UYD | E10: SEREMI | F10: 2605107634 | G10: LOS ANDES
A11: SO/6370-22 | B11: 179972 | D11: CDA | E11: SAG | F11: 0520260011763CDA | G11: LOS ANDES
A12: SO/6370-23 | B12: 180001 | D12: CDA | E12: SEREMI | F12: 260595504 | G12: LOS ANDES
A13: SO/6370-23 | B13: 180001 | D13: UYD | E13: SEREMI | F13: 260597318 | G13: LOS ANDES
A14: SO/6370-23 | B14: 180001 | D14: CDA | E14: SAG | F14: 0520260010619CDA | G14: LOS ANDES
A15: SO/6370-26 | B15: 180023 | D15: CDA | E15: SEREMI | F15: 260598254 | G15: LOS ANDES
A16: SO/6370-26 | B16: 180023 | D16: UYD | E16: SEREMI | F16: 260599583 | G16: LOS ANDES
A17: SO/6370-26 | B17: 180023 | D17: CDA | E17: SAG | F17: 0520260010919CDA | G17: LOS ANDES
A18: CN 25221 | B18: 180040 | D18: CDA | E18: SEREMI | F18: 2605101685 | G18: LOS ANDES
A19: CN 25221 | B19: 180040 | D19: UYD | E19: SEREMI | F19: 2605107573 | G19: LOS ANDES
A20: CN 25221 | B20: 180040 | D20: CDA | E20: SAG | F20: 0520260011333CDA | G20: LOS ANDES
A21: SO/6360-28 | B21: 180056 | D21: CDA | E21: SEREMI | F21: 2605101914 | G21: LOS ANDES
A22: SO/6360-28 | B22: 180056 | D22: UYD | E22: SEREMI | F22: 2605102768 | G22: LOS ANDES
A23: SO/6360-28 | B23: 180056 | D23: CDA | E23: SAG | F23: 0520260011336CDA | G23: LOS ANDES
A24: SO/6360-25 | B24: 180057 | D24: CDA | E24: SEREMI | F24: 2605100691 | G24: LOS ANDES
A25: SO/6360-25 | B25: 180057 | D25: UYD | E25: SEREMI | F25: 2605101997 | G25: LOS ANDES
A26: SO/6360-25 | B26: 180057 | D26: CDA | E26: SAG | F26: 0520260011220CDA | G26: LOS ANDES
A27: SO/6356-4 | B27: 180059 | D27: CDA | E27: SEREMI | F27: 2605101437 | G27: LOS ANDES
A28: SO/6356-4 | B28: 180059 | D28: UYD | E28: SEREMI | F28: 2605101999 | G28: LOS ANDES
A29: SO/6356-4 | B29: 180059 | D29: CDA | E29: SAG | F29: 0520260011285CDA | G29: LOS ANDES
A30: O/87304-3 | B30: 180066 | D30: CDA | E30: SEREMI | F30: 2605106858 | G30: LOS ANDES
A31: O/87304-3 | B31: 180066 | D31: UYD | E31: SEREMI | F31: 2605107743 | G31: LOS ANDES
A32: O/87304-3 | B32: 180066 | D32: CDA | E32: SAG | F32: 0520260011841CDA | G32: LOS ANDES
A33: SO/6356-5 | B33: 180067 | D33: CDA | E33: SEREMI | F33: 2605100503 | G33: LOS ANDES
A34: SO/6356-5 | B34: 180067 | D34: UYD | E34: SEREMI | F34: 2605102001 | G34: LOS ANDES
A35: SO/6356-5 | B35: 180067 | D35: CDA | E35: SAG | F35: 0520260011208CDA | G35: LOS ANDES
A36: CN 6357-10 | B36: 180070 | D36: CDA | E36: SEREMI | F36: 2605106749 | G36: LOS ANDES
A37: CN 6357-10 | B37: 180070 | D37: UYD | E37: SEREMI | F37: 2605107710 | G37: LOS ANDES
A38: CN 6357-10 | B38: 180070 | D38: CDA | E38: SAG | F38: 0520260011782CDA | G38: LOS ANDES
A39: CN 6358-10 | B39: 180072 | D39: CDA | E39: SEREMI | F39: 2605104506 | G39: LOS ANDES
A40: CN 6358-10 | B40: 180072 | D40: UYD | E40: SEREMI | F40: 2605105058 | G40: LOS ANDES
...
